Workbook

Sheet Sheet1
A1: Area | B1: type | C1: Name | D1: year | G1: year | H1: 2013
A2: 18 | B2: Forest | C2: Natural Vegetation | D2: 1975
A3: 35537 | B3: Savanna | C3: Natural Vegetation | D3: 1975 | G3: Row Labels | H3: 加總 - Area
A4: 1064 | B4: Wetland - floodplain | C4: Natural Vegetation | D4: 1975 | G4: Barren/Urban | H4: 2315 | I4: =GETPIVOTDATA("Area",$G$3,"Name","Barren/Urban")*4 -> #REF!
A5: 12244 | B5: Steppe | C5: Natural Vegetation | D5: 1975 | G5: Crop Land/Pasture | H5: 26858 | I5: =GETPIVOTDATA("Area",$G$3,"Name","Crop Land/Pasture")*4 -> #REF!
A6: 10212 | B6: Agriculture | C6: Crop Land/Pasture | D6: 1975 | G6: Natural Vegetation | H6: 38666 | I6: =GETPIVOTDATA("Area",$G$3,"Name","Natural Vegetation")*4 -> #REF!
A7: 169 | B7: Water bodies | C7: Natural Vegetation | D7: 1975 | G7: Grand Total | H7: 67839 | I7: =SUM(I4:I6) -> #REF!
A8: 988 | B8: Rocky land | C8: Barren/Urban | D8: 1975
A9: 944 | B9: Bare soil | C9: Barren/Urban | D9: 1975
A10: 69 | B10: Settlements | C10: Barren/Urban | D10: 1975
A11: 126 | B11: Irrigated agriculture | C11: Crop Land/Pasture | D11: 1975
A12: 1748 | B12: Gallery forest and riparian forest | C12: Natural Vegetation | D12: 1975
A13: 2 | B13: Bowe | C13: Barren/Urban | D13: 1975
A14: 2 | B14: Agriculture in shallows and recession | C14: Crop Land/Pasture | D14: 1975
A15: 4 | B15: Woodland | C15: Natural Vegetation | D15: 1975
A16: 4712 | B16: Sahelian short grass savanna | C16: Natural Vegetation | D16: 1975
A17: 11 | B17: Forest | C17: Natural Vegetation | D17: 2013
A18: 21148 | B18: Savanna | C18: Natural Vegetation | D18: 2013
A19: 1466 | B19: Wetland - floodplain | C19: Natural Vegetation | D19: 2013
... A30: 2 | B30: Bowe | C30: Barren/Urban | D30: 2013
A31: 3 | B31: Agriculture in shallows and recession | C31: Crop Land/Pasture | D31: 2013 | H31: 1975 | I31: 2000 | J31: 2013 | K31: 2025
A32: 4 | B32: Woodland | C32: Natural Vegetation | D32: 2013 | G32: Barren/Urban | H32: 8012 | I32: 8440 | J32: 9260 | K32: 10154
A33: 3425 | B33: Sahelian short grass savanna | C33: Natural Vegetation | D33: 2013 | G33: Crop Land/Pasture | H33: 41360 | I33: 74312 | J33: 107432 | K33: 150186
A34: 12 | B34: Open mine | C34: Barren/Urban | D34: 2013 | G34: Natural Vegetation | H34: 221984 | I34: 188604 | J34: 154664 | K34: 111016
A35: 17 | B35: Forest | C35: Natural Vegetation | D35: 2000 | G35: Total | H35: =SUM(H32,H33,H34) -> 271356 | I35: =SUM(I32,I33,I34) -> 271356 | J35: =SUM(J32,J34,J33) -> 271356 | K35: =SUM(K32,K33,K34) -> 271356
A36: 28138 | B36: Savanna | C36: Natural Vegetation | D36: 2000 | G36: Probability | H36: =H35/274200 -> 0.98962801 | I36: =I35/274200 -> 0.98962801 | J36: =J35/274200 -> 0.98962801 | K36: =K35/274200 -> 0.98962801
A37: 1255 | B37: Wetland - floodplain | C37: Natural Vegetation | D37: 2000
A38: 12125 | B38: Steppe | C38: Natural Vegetation | D38: 2000
A39: 18405 | B39: Agriculture | C39: Crop Land/Pasture | D39: 2000
A40: 338 | B40: Water bodies | C40: Natural Vegetation | D40: 2000
A41: 784 | B41: Rocky land | C41: Barren/Urban | D41: 2000
A42: 1209 | B42: Bare soil | C42: Barren/Urban | D42: 2000
A43: 115 | B43: Settlements | C43: Barren/Urban | D43: 2000
A44: 171 | B44: Irrigated agriculture | C44: Crop Land/Pasture | D44: 2000
A45: 1425 | B45: Gallery forest and riparian forest | C45: Natural Vegetation | D45: 2000
A46: 2 | B46: Bowe | C46: Barren/Urban | D46: 2000
A47: 2 | B47: Agriculture in shallows and recession | C47: Crop Land/Pasture | D47: 2000
A48: 4 | B48: Woodland | C48: Natural Vegetation | D48: 2000
A49: 3849 | B49: Sahelian short grass savanna | C49: Natural Vegetation | D49: 2000

Sheet Sheet2
A1: Mineral FertiIizer Use by Crop | B1: PLANTED AREA | E1: NUTRIENT APPLIED | N1: NUTRIENT APPLICATION RATE | W1: CROP SHARE OF TOTAL NUTRIENT USE
A2: BURKINA FASO | B2: ha | E2: Metric tonnes of nutrients | N2: Kg nutrient/ha | W2: %
E3: N | H3: P2O5 | K3: K2O | N3: N | Q3: P2O5 | T3: K2O | W3: N | Z3: P2O5 | AC3: K2O
A4: CROP | B4: 2015 | C4: 2016 | D4: 2017 | E4: 2015 | F4: 2016 | G4: 2017 | H4: 2015 | I4: 2016 | J4: 2017 | K4: 2015 | L4: 2016 | M4: 2017 | N4: 2015 | O4: 2016 | P4: 2017 | Q4: 2015 | R4: 2016 | S4: 2017 | T4: 2015 | U4: 2016 | V4: 2017 | W4: 2015 | X4: 2016 | Y4: 2017 | Z4: 2015 | AA4: 2016 | AB4: 2017 | AC4: 2015 | AD4: 2016 | AE4: 2017
A6: Cotton | B6: 651000 | C6: 657000 | D6: 645000 | E6: 31636 | F6: 38064 | G6: 41050 | H6: 19555 | I6: 23271 | J6: 24390 | K6: 19178 | L6: 22886 | M6: 24390 | N6: =IFERROR(E6*1000/B6,"-") -> 48.596006 | O6: =IFERROR(F6*1000/C6,"-") -> 57.936073 | P6: =IFERROR(G6*1000/D6,"-") -> 63.643411 | Q6: =IFERROR(H6*1000/B6,"-") -> 30.038402 | R6: =IFERROR(I6*1000/C6,"-") -> 35.420091 | S6: =IFERROR(J6*1000/D6,"-") -> 37.813953 | T6: =IFERROR(K6*1000/B6,"-") -> 29.459293 | U6: =IFERROR(L6*1000/C6,"-") -> 34.834094 | V6: =IFERROR(M6*1000/D6,"-") -> 37.813953 | W6: =IFERROR(E6/E$20,"-") -> - | X6: =IFERROR(F6/F$20,"-") -> - | Y6: =IFERROR(G6/G$20,"-") -> - | Z6: =IFERROR(H6/H$20,"-") -> - | AA6: =IFERROR(I6/I$20,"-") -> - | AB6: =IFERROR(J6/J$20,"-") -> - | AC6: =IFERROR(K6/K$20,"-") -> - | AD6: =IFERROR(L6/L$20,"-") -> - | AE6: =IFERROR(M6/M$20,"-") -> -
A7: Maize | B7: 749000 | C7: 820000 | D7: 911000 | E7: 26533 | F7: 26973 | G7: 32643 | H7: 14316 | I7: 15219 | J7: 17651 | K7: 9730 | L7: 10342 | M7: 12095 | N7: =IFERROR(E7*1000/B7,"-") -> 35.424566 | O7: =IFERROR(F7*1000/C7,"-") -> 32.893902 | P7: =IFERROR(G7*1000/D7,"-") -> 35.832053 | Q7: =IFERROR(H7*1000/B7,"-") -> 19.113485 | R7: =IFERROR(I7*1000/C7,"-") -> 18.559756 | S7: =IFERROR(J7*1000/D7,"-") -> 19.375412 | T7: =IFERROR(K7*1000/B7,"-") -> 12.990654 | U7: =IFERROR(L7*1000/C7,"-") -> 12.612195 | V7: =IFERROR(M7*1000/D7,"-") -> 13.276619 | W7: =IFERROR(E7/E$20,"-") -> - | X7: =IFERROR(F7/F$20,"-") -> - | Y7: =IFERROR(G7/G$20,"-") -> - | Z7: =IFERROR(H7/H$20,"-") -> - | AA7: =IFERROR(I7/I$20,"-") -> - | AB7: =IFERROR(J7/J$20,"-") -> - | AC7: =IFERROR(K7/K$20,"-") -> - | AD7: =IFERROR(L7/L$20,"-") -> - | AE7: =IFERROR(M7/M$20,"-") -> -
A8: Sorghum | B8: 154000 | C8: 144000 | D8: 173000 | E8: 3154 | F8: 2816 | G8: 3154 | H8: 2521 | I8: 2552 | J8: 2861 | K8: 1812 | L8: 1846 | M8: 2042 | N8: =IFERROR(E8*1000/B8,"-") -> 20.480519 | O8: =IFERROR(F8*1000/C8,"-") -> 19.555556 | P8: =IFERROR(G8*1000/D8,"-") -> 18.231214 | Q8: =IFERROR(H8*1000/B8,"-") -> 16.37013 | R8: =IFERROR(I8*1000/C8,"-") -> 17.722222 | S8: =IFERROR(J8*1000/D8,"-") -> 16.537572 | T8: =IFERROR(K8*1000/B8,"-") -> 11.766234 | U8: =IFERROR(L8*1000/C8,"-") -> 12.819444 | V8: =IFERROR(M8*1000/D8,"-") -> 11.803468 | W8: =IFERROR(E8/E$20,"-") -> - | X8: =IFERROR(F8/F$20,"-") -> - | Y8: =IFERROR(G8/G$20,"-") -> - | Z8: =IFERROR(H8/H$20,"-") -> - | AA8: =IFERROR(I8/I$20,"-") -> - | AB8: =IFERROR(J8/J$20,"-") -> - | AC8: =IFERROR(K8/K$20,"-") -> - | AD8: =IFERROR(L8/L$20,"-") -> - | AE8: =IFERROR(M8/M$20,"-") -> -
A9: Millet | B9: 1192000 | C9: 1160000 | D9: 1187000 | E9: 1267 | F9: 1334 | G9: 1235 | H9: 869 | I9: 815 | J9: 943 | K9: 597 | L9: 608 | M9: 673 | N9: =IFERROR(E9*1000/B9,"-") -> 1.0629195 | O9: =IFERROR(F9*1000/C9,"-") -> 1.15 | P9: =IFERROR(G9*1000/D9,"-") -> 1.0404381 | Q9: =IFERROR(H9*1000/B9,"-") -> 0.72902685 | R9: =IFERROR(I9*1000/C9,"-") -> 0.70258621 | S9: =IFERROR(J9*1000/D9,"-") -> 0.79443976 | T9: =IFERROR(K9*1000/B9,"-") -> 0.50083893 | U9: =IFERROR(L9*1000/C9,"-") -> 0.52413793 | V9: =IFERROR(M9*1000/D9,"-") -> 0.56697557 | W9: =IFERROR(E9/E$20,"-") -> - | X9: =IFERROR(F9/F$20,"-") -> - | Y9: =IFERROR(G9/G$20,"-") -> - | Z9: =IFERROR(H9/H$20,"-") -> - | AA9: =IFERROR(I9/I$20,"-") -> - | AB9: =IFERROR(J9/J$20,"-") -> - | AC9: =IFERROR(K9/K$20,"-") -> - | AD9: =IFERROR(L9/L$20,"-") -> - | AE9: =IFERROR(M9/M$20,"-") -> -
A10: Rice | B10: 144000 | C10: 142000 | D10: 170000 | E10: 1671 | F10: 2144 | G10: 2924 | H10: 902 | I10: 849 | J10: 1351 | K10: 624 | L10: 608 | M10: 919 | N10: =IFERROR(E10*1000/B10,"-") -> 11.604167 | O10: =IFERROR(F10*1000/C10,"-") -> 15.098592 | P10: =IFERROR(G10*1000/D10,"-") -> 17.2 | Q10: =IFERROR(H10*1000/B10,"-") -> 6.2638889 | R10: =IFERROR(I10*1000/C10,"-") -> 5.9788732 | S10: =IFERROR(J10*1000/D10,"-") -> 7.9470588 | T10: =IFERROR(K10*1000/B10,"-") -> 4.3333333 | U10: =IFERROR(L10*1000/C10,"-") -> 4.2816901 | V10: =IFERROR(M10*1000/D10,"-") -> 5.4058824 | W10: =IFERROR(E10/E$20,"-") -> - | X10: =IFERROR(F10/F$20,"-") -> - | Y10: =IFERROR(G10/G$20,"-") -> - | Z10: =IFERROR(H10/H$20,"-") -> - | AA10: =IFERROR(I10/I$20,"-") -> - | AB10: =IFERROR(J10/J$20,"-") -> - | AC10: =IFERROR(K10/K$20,"-") -> - | AD10: =IFERROR(L10/L$20,"-") -> - | AE10: =IFERROR(M10/M$20,"-") -> -
A11: Cow pea | B11: 168000 | C11: 165000 | D11: 228000 | E11: 308 | F11: 437 | G11: 451 | H11: 247 | I11: 370 | J11: 363 | K11: 171 | L11: 249 | M11: 249 | N11: =IFERROR(E11*1000/B11,"-") -> 1.8333333 | O11: =IFERROR(F11*1000/C11,"-") -> 2.6484848 | P11: =IFERROR(G11*1000/D11,"-") -> 1.9780702 | Q11: =IFERROR(H11*1000/B11,"-") -> 1.4702381 | R11: =IFERROR(I11*1000/C11,"-") -> 2.2424242 | S11: =IFERROR(J11*1000/D11,"-") -> 1.5921053 | T11: =IFERROR(K11*1000/B11,"-") -> 1.0178571 | U11: =IFERROR(L11*1000/C11,"-") -> 1.5090909 | V11: =IFERROR(M11*1000/D11,"-") -> 1.0921053 | W11: =IFERROR(E11/E$20,"-") -> - | X11: =IFERROR(F11/F$20,"-") -> - | Y11: =IFERROR(G11/G$20,"-") -> - | Z11: =IFERROR(H11/H$20,"-") -> - | AA11: =IFERROR(I11/I$20,"-") -> - | AB11: =IFERROR(J11/J$20,"-") -> - | AC11: =IFERROR(K11/K$20,"-") -> - | AD11: =IFERROR(L11/L$20,"-") -> - | AE11: =IFERROR(M11/M$20,"-") -> -
A12: Fruits and vegetables | B12: 50000 | C12: 57000 | D12: 64000 | E12: 322 | F12: 458 | G12: 472 | H12: 203 | I12: 306 | J12: 299 | K12: 164 | L12: 239 | M12: 238 | N12: =IFERROR(E12*1000/B12,"-") -> 6.44 | O12: =IFERROR(F12*1000/C12,"-") -> 8.0350877 | P12: =IFERROR(G12*1000/D12,"-") -> 7.375 | Q12: =IFERROR(H12*1000/B12,"-") -> 4.06 | R12: =IFERROR(I12*1000/C12,"-") -> 5.3684211 | S12: =IFERROR(J12*1000/D12,"-") -> 4.671875 | T12: =IFERROR(K12*1000/B12,"-") -> 3.28 | U12: =IFERROR(L12*1000/C12,"-") -> 4.1929825 | V12: =IFERROR(M12*1000/D12,"-") -> 3.71875 | W12: =IFERROR(E12/E$20,"-") -> - | X12: =IFERROR(F12/F$20,"-") -> - | Y12: =IFERROR(G12/G$20,"-") -> - | Z12: =IFERROR(H12/H$20,"-") -> - | AA12: =IFERROR(I12/I$20,"-") -> - | AB12: =IFERROR(J12/J$20,"-") -> - | AC12: =IFERROR(K12/K$20,"-") -> - | AD12: =IFERROR(L12/L$20,"-") -> - | AE12: =IFERROR(M12/M$20,"-") -> -
A13: Sugar cane | B13: 4000 | C13: 4000 | D13: 4000 | E13: 505 | F13: 659 | G13: 162 | H13: 128 | I13: 479 | J13: 220 | K13: 498 | L13: 422 | M13: 538 | N13: =IFERROR(E13*1000/B13,"-") -> 126.25 | O13: =IFERROR(F13*1000/C13,"-") -> 164.75 | P13: =IFERROR(G13*1000/D13,"-") -> 40.5 | Q13: =IFERROR(H13*1000/B13,"-") -> 32 | R13: =IFERROR(I13*1000/C13,"-") -> 119.75 | S13: =IFERROR(J13*1000/D13,"-") -> 55 | T13: =IFERROR(K13*1000/B13,"-") -> 124.5 | U13: =IFERROR(L13*1000/C13,"-") -> 105.5 | V13: =IFERROR(M13*1000/D13,"-") -> 134.5 | W13: =IFERROR(E13/E$20,"-") -> - | X13: =IFERROR(F13/F$20,"-") -> - | Y13: =IFERROR(G13/G$20,"-") -> - | Z13: =IFERROR(H13/H$20,"-") -> - | AA13: =IFERROR(I13/I$20,"-") -> - | AB13: =IFERROR(J13/J$20,"-") -> - | AC13: =IFERROR(K13/K$20,"-") -> - | AD13: =IFERROR(L13/L$20,"-") -> - | AE13: =IFERROR(M13/M$20,"-") -> -
E14: =SUM(E7,E8,E9,E10,E11,E12,E13) -> 33760 | F14: =SUM(F7,F8,F9,F10,F11,F12,F13) -> 34821 | G14: =SUM(G7,G8,G9,G10,G11,G12,G13) -> 41041 | H14: =SUM(H7,H8,H9,H10,H11,H12,H13) -> 19186 | I14: =SUM(I7,I9,I8,I10,I11,I12,I13) -> 20590 | J14: =SUM(J7,J8,J9,J10,J11,J12,J13) -> 23688 | K14: =SUM(K7,K8,K9,K10,K11,K12,K13) -> 13596 | L14: =SUM(L7,L8,L9,L10,L11,L12,L13) -> 14314 | M14: =SUM(M7,M8,M9,M10,M11,M12,M13) -> 16754
A15: Total | B15: =SUM(B6:B13) -> 3112000 | C15: =SUM(C6:C13) -> 3149000 | D15: =SUM(D6:D13) -> 3382000 | E15: =SUM(E6:E13) -> 65396 | F15: =SUM(F6:F13) -> 72885 | G15: =SUM(G6:G13) -> 82091 | H15: =SUM(H6:H13) -> 38741 | I15: =SUM(I6:I13) -> 43861 | ... M15: =SUM(M6:M13) -> 41144 | W15: =SUM(W6:W13) -> 0 | X15: =SUM(X6:X13) -> 0 | Y15: =SUM(Y6:Y13) -> 0 | Z15: =SUM(Z6:Z13) -> 0 | AA15: =SUM(AA6:AA13) -> 0 | AB15: =SUM(AB6:AB13) -> 0 | AC15: =SUM(AC6:AC13) -> 0 | AD15: =SUM(AD6:AD13) -> 0 | AE15: =SUM(AE6:AE13) -> 0
C16: Fertilizer | D16: N;P/ Capita | E16: =(E15/18718000) -> 0.0034937493 | F16: =(F15/19275500) -> 0.0037812249 | G16: =(G15/19835858) -> 0.0041385152 | H16: =(H15/18718019) -> 0.0020697169 | I16: =(I15/19275498) -> 0.0022754795 | J16: =(J15/19835858) -> 0.0024237923 | S16: for food | T16: PB
B17: 2023-24 | C17: From animal | D17: N;P/ Capita | E17: =(165600/23251485) -> 0.0071221257 | H17: =(69000/23251485) -> 0.0029675524 | N17: Total N per capita | P17: =SUM(G16,E17) -> 0.011260641 | Q17: =(P17*1000) -> 11.260641 | R17: =(Q17/2) -> 5.6303205 | S17: =(R17/2) -> 2.8151602 | T17: =(S17/5.7) -> 0.49388776 | V17: =((5.7-2.81516)/5.7) -> 0.50611228
C18: Sources: | N18: Total P per capita | P18: 0.003955 | Q18: =(P18*1000) -> 3.955 | R18: =(Q18/2) -> 1.9775 | S18: =(R18/2) -> 0.98875 | U18: =(S18*0.4364) -> 0.4314905 | V18: =((0.52-0.43)/0.52) -> 0.17307692
C19: AfricaFertilizer.Org (AFO) initiative hosted by the International Fertilizer Development Center (IFDC). | X19: Loss to Soil | Y19: Total Input
C20: Area data come from the Ministry of Agriculture's permanent agricultural surveys (DGESS - Ministry of Agriculture, EPA, 2016-2017). | V20: Nitrogen
P21: Total P per capita remaining in soil | V21: Phosphorus
C22: Notes:
C23: The consumption estimates presented here relate to mineral fertilizers only. 2017 refers to the period from January 2017 to December 2017.
C24: Please note that the total quantities of nutrients reported here may be different from the totals reported in the IFASTAT consumption database.
S25: Blue water PB | U25: =(36.4/583) -> 0.062435678
C26: Copyright © 2022 International Fertilizer Association – All Rights Reserved
G33: 2015 | H33: 2016 | I33: 2017 | J33: 2015 | K33: 2016 | L33: 2017
G36: 2015 | H36: 2016 | I36: 2017
F37: N | G37: 33760 | H37: 34821 | I37: 41041
F38: P2O5 | G38: 19186 | H38: 20590 | I38: 23688

Sheet PopulationTrajectory
A1: Population trajectory — supporting data
A3: Companion to Supplementary Table S1 (population projections). UN medium-variant, UN DESA (2024)
A5: 1. Population trajectory (Burkina Faso, UN medium-variant, UN DESA 2024)
A6: Year | B6: Population
A7: 2025 | B7: 24075000
A8: 2050 | B8: 37304000
A9: 2075 | B9: 46764000
A10: 2100 | B10: 49846000

Sheet LandSystemChange_Agri
A1: Land-system-change AESI: agricultural-land recomputation
A3: Context
A4: Table 1's Land-System Change AESI comprises all agricultural land
A5: (cropland + pasture together), matching te Wierik et al.'s (2025) global agricultural-land footprint definition (manuscript Table 1).
A10: Corrected inputs | B10: Value | C10: Unit | D10: Source
A11: Burkina Faso cropland (actual, 2025) | B11: 6 | C11: Mha | D11: This study (manuscript Section 3.1.3 / Table 1; DGESS/EPA permanent agricultural survey, 2016-2017)
A12: Burkina Faso permanent pasture (% of land area) | B12: 21.93 | C12: % | D12: World Bank / FAOSTAT, 2023 (matches CIA World Factbook, 2018 estimate, independently)
A13: Burkina Faso total land area | B13: 27.1356 | C13: Mha | D13: Sheet1 land-use totals (K35, 271,356 km2)
A14: Burkina Faso permanent pasture (derived) | B14: =B12*B13/100 -> 5.9508371 | C14: Mha | D14: Computed as pasture % x total land area
A15: Burkina Faso agricultural land (2025) | B15: =B11+B14 -> 11.950837 | C15: Mha | D15: Computed as cropland + pasture
A17: Global agricultural land, current use | B17: 4800 | C17: Mha | D17: te Wierik et al. (2025); '48 Mkm2' already cited in manuscript Section 3.1.3
A18: Global agricultural-land boundary (central) | B18: 4136 | C18: Mha | D18: Conijn et al. (2018); 50% land-conversion threshold, 2010 land use
A20: Downscaled boundary (land-area share) | B20: =B15/B17*B18 -> 10.297638 | C20: Mha | D20: SOS_BFA,Agri = (A_BFA / A_World) x FSB_World,Agri
A21: Pressure-to-boundary ratio, 2025 | B21: =B15/B20 -> 1.1605416 | C21: ratio | D21: Computed as agricultural land / downscaled boundary
A24: for the food-security-required-land indicator, which concerns cereal cultivation specifically
A25: Cropland-only ratio, 2025 (6.0 / 4.97 Mha) | B25: =B11/4.97 -> 1.2072435 | C25: ratio

Sheet LiteratureReview
A1: Literature review: national downscaling of food-system planetary boundaries (expanded per te Wierik et al., 2025)
A4: Seven of nine planetary boundaries are already transgressed, and food systems are consistently identified as a dominant driver across climate, land, freshwater, and nutrient domains (Rockström et al., 2009; te Wierik et al., 2025). Translating these global limits into boundaries that a country, sector, or business can act on -- "downscaling" -- has therefore become an active sub-field of its own (Bai et al., 2024).
A5: A growing body of national- and sub-national-scale applications now spans very different geographies and allocation choices: Nykvist et al. (2013) and Dao et al. (2018) established early country-level downscaling principles (Sweden and Switzerland); Huang et al. (2020) applied a dynamic, population-weighted downscaling method to Taiwan, Røkås & Gómez-Baggethun (2025) downscaled a hybrid top-down/bottom-up set of boundaries to Norway; and Lind, Friis & Vea (2025, CONCITO/DTU Sustain) produced the most methodologically comparable case to this study, downscaling six boundaries to Denmark using both equal-per-capita and historical-responsibility allocation. At the sector level, Conijn et al. (2018) and te Wierik et al. (2025) define the global food-system boundary (FSB) values this study adopts directly (Table 1).
A7: This study assesses whether a sahelian country like Burkina faso could feed itself within a dedicated SOS.
A9: Comparison of national/sub-global downscaling studies
A10: Study | B10: Year | C10: Geographic scope | D10: PB domains covered | E10: Downscaling method(s) | F10: Agricultural land treatment | G10: Relation to this study
A11: Nykvist, Persson & Persson | B11: 2013 | C11: Sweden | D11: Climate, land, freshwater, biogeochemical flows, biodiversity | E11: Country-share downscaling principles (one of the earliest applications); no single method prescribed | F11: Not disaggregated (land-system change treated generically) | G11: Source of this study's general “selected downscaling method” citation (Section 2.2, 2.3); land-area-share equation follows this family of approaches.
A12: Dao, Peduzzi & Friot | B12: 2018 | C12: Switzerland | D12: Climate, land, freshwater, biogeochemical flows, biodiversity | E12: Per-capita / equal-share downscaling, with historical-responsibility variants for climate | F12: Not disaggregated (land footprint, not cropland vs pasture) | G12: Per-capita climate-allocation principle cited for the national AESI convention (manuscript Sections 2.3 and 3.1.1).
A13: Huang, Hu & Kuo | B13: 2020 | C13: Taiwan | D13: Climate, ocean acidification, biogeochemical flows (N, P), land-system change, freshwater use | E13: Global-share allocation by domain; dynamic normalization/weighting factors (DNF, DWF) evolve the allocation with population over time. | F13: Forest-cover-to-potential-forest ratio (Anthropized Land from potential forest cover); no cropland/pasture distinction | G13: DNF/DWF method adopted directly; land-system-change method NOT followed.
A14: Conijn, Bindraban, Schröder & Jongschaap | B14: 2018 | C14: Global (sectoral) | D14: Land-system change (agricultural land only) | E14: Global 50%-land-conversion threshold (2010 land use), not a national downscaling method | F14: Agricultural land as a whole (cropland + pasture) | G14: Supplies this study's global agricultural-land central-value boundary (4,136 Mha; Table 1, footnote a).
A15: Bai, Hasan, Andersen et al. | B15: 2024 | C15: Cities and businesses (synthesis) | D15: All 8 Earth-system boundaries (synthesis of 40 studies) | E15: Taxonomy of 11 sharing principles (equality, responsibility, capability, basic needs, grandfathering, etc.); no single method | F15: Not a primary study; land/nutrient boundaries discussed only via cited sub-global case studies | G15: General framing reference for “downscaling as a distinct sub-field” (Section 1); this study's chosen principles (population/land-area share) sit within Bai et al.'s “equality” and “basic needs” categories.
A16: Røkås & Gómez-Baggethun | B16: 2025 | C16: Norway | D16: Climate, ocean acidification, phosphorus, nitrogen, biosphere integrity, land-system change, freshwater | E16: Hybrid: top-down per-capita + historical-responsibility for climate/ocean acidification; bottom-up national-policy targets for land, freshwater, nutrients, biodiversity | F16: Forest-cover-to-potential-forest ratio only (Bryn et al., 2013 method); phosphorus derived bottom-up from agronomic soil-nutrient requirements, not an area share | G16: Cited in the Introduction as a national downscaling application; the clearest bottom-up alternative to this study's area-share approach.
A17: Lind, Friis & Vea (CONCITO/DTU Sustain) | B17: 2025 | C17: Denmark | D17: Climate, land-system change, freshwater use, nitrogen, phosphorus, biosphere integrity | E17: Equal-per-capita AND historical-responsibility allocation (explicit “debt”/payback-period equations) for climate and footprint indicators; bottom-up national modelling for territorial land, freshwater and nutrient indicators | F17: Explicitly disaggregates cropland, total agricultural/anthropized land, and total land occupation (crop + pasture + forestry) | G17: The single most comparable national case study.
A18: te Wierik, DeClerck, Beusen et al. | B18: 2025 | C18: Global (food system sector) | D18: Climate, land-system change, freshwater use, nitrogen, phosphorus | E18: No single method: IAM-optimized allocation for climate; proportional-reduction-from-current-share for freshwater/N/P; multi-scale (global/biome/ecoregion) intactness thresholds for land | F18: Reports the global food-system land footprint (48 Mkm²) explicitly as ~16 Mkm² cropland + ~32 Mkm² permanent meadow/pasture combined | G18: Source of every global FSB reference value in this study's Table 1 (“Adapted from te Wierik et al., 2025; Willett et al., 2019”); its land-scope finding (grazing land raising ecoregion transgression from 5% to 34%) directly motivates this study's cropland-to-agricultural-land extension.
A19: This study (Ouattara et al.) | B19: 2026 | C19: Burkina Faso | D19: Climate, land-system change, freshwater use, nitrogen, phosphorus (one framework across all five) | E19: Population share (climate), land-area intensity (freshwater, N, P) and land-area share (land-system change), dynamically re-weighted via DNF/DWF method; compared against AP, GF and RE principles | F19: Agricultural land, cropland plus pasture, linked forward to a life-cycle cereal-demand projection through 2100 — not attempted in any of the above | G19: —

Sheet MultiPrincipleDownscaling
A1: Multi-principle downscaling and dynamic Monte Carlo — supporting calculations
A5: 1. Deterministic downscaled boundary (SOS) and ASR by sharing principle, domain, and year
A6: Domain | B6: Year | C6: Principle | D6: Current impact (EI) | E6: Unit | F6: Downscaled boundary (SOS) | G6: ASR = EI / SOS
A7: Climate change | B7: 2025 | C7: EPC | D7: 0.06531 | E7: Gt CO2eq | F7: 0.014748 | G7: 4.4283
A8: Climate change | B8: 2025 | C8: AP | D8: 0.06531 | E8: Gt CO2eq | F8: 0.205214 | G8: 0.3183
A9: Climate change | B9: 2025 | C9: GF | D9: 0.06531 | E9: Gt CO2eq | F9: 0.01938 | G9: 3.37
A10: Climate change | B10: 2025 | C10: RE | D10: 0.06531 | E10: Gt CO2eq | F10: 0.78719 | G10: 0.083
A11: Climate change | B11: 2050 | C11: EPC | D11: 0.06531 | E11: Gt CO2eq | F11: 0.0193 | G11: 3.384
A12: Climate change | B12: 2050 | C12: AP | D12: 0.06531 | E12: Gt CO2eq | F12: 0.268545 | G12: 0.2432
A13: Climate change | B13: 2050 | C13: GF | D13: 0.06531 | E13: Gt CO2eq | F13: 0.01938 | G13: 3.37
A14: Climate change | B14: 2050 | C14: RE | D14: 0.06531 | E14: Gt CO2eq | F14: 1.030125 | G14: 0.0634
A15: Climate change | B15: 2075 | C15: EPC | D15: 0.06531 | E15: Gt CO2eq | F15: 0.022811 | G15: 2.8631
A16: Climate change | B16: 2075 | C16: AP | D16: 0.06531 | E16: Gt CO2eq | F16: 0.317397 | G16: 0.2058
A17: Climate change | B17: 2075 | C17: GF | D17: 0.06531 | E17: Gt CO2eq | F17: 0.01938 | G17: 3.37
A18: Climate change | B18: 2075 | C18: RE | D18: 0.06531 | E18: Gt CO2eq | F18: 1.217518 | G18: 0.0536
... A70: Land-system change | B70: 2100 | C70: GF | D70: 0.06 | E70: Mkm2 (EI = cropland 6.0 Mha) | F70: 0.0517 | G70: 1.1605
A72: 2. Pooled dynamic Monte Carlo summary (N = 2,000; sharing-principle choice + FSB boundary-value uncertainty), by domain and year (main-text Figure 8; Supplementary Figures S6 and S7)
A73: Domain | B73: Year | C73: Median ASR | D73: 5th percentile ASR | E73: 95th percentile ASR | F73: Frequency of no-transgression (f_i,t)
A74: Climate change | B74: 2025 | C74: 1.7298 | D74: 0.0802 | E74: 4.517 | F74: 0.5
A75: Climate change | B75: 2050 | C75: 0.2556 | D75: 0.0616 | E75: 3.4853 | F75: 0.5055
A76: Climate change | B76: 2075 | C76: 2.6984 | D76: 0.052 | E76: 3.4304 | F76: 0.495
A77: Climate change | B77: 2100 | C77: 0.2022 | D77: 0.0485 | E77: 3.4313 | F77: 0.5005
A78: Freshwater use | B78: 2025 | C78: 0.603 | D78: 0.2945 | E78: 7.2388 | F78: 0.6435
A79: Freshwater use | B79: 2050 | C79: 0.6151 | D79: 0.2248 | E79: 5.5084 | F79: 0.647
A80: Freshwater use | B80: 2075 | C80: 0.5938 | D80: 0.192 | E80: 4.6453 | F80: 0.6505
A81: Freshwater use | B81: 2100 | C81: 0.599 | D81: 0.1789 | E81: 4.3703 | F81: 0.646
A82: Nitrogen | B82: 2025 | C82: 0.1459 | D82: 0.0086 | E82: 1.4118 | F82: 0.727
A83: Nitrogen | B83: 2050 | C83: 0.1087 | D83: 0.0067 | E83: 1.4007 | F83: 0.7285
A84: Nitrogen | B84: 2075 | C84: 0.0928 | D84: 0.0055 | E84: 1.3912 | F84: 0.7295
A85: Nitrogen | B85: 2100 | C85: 0.0864 | D85: 0.0052 | E85: 1.4096 | F85: 0.7155
... A93: Land-system change | B93: 2100 | C93: 0.2963 | D93: 0.0213 | E93: 1.1605 | F93: 0.6635
A95: 3. Monte Carlo frequency of no-transgression, stratified by principle held fixed (boundary-value uncertainty only) — matches Supplementary Table S9
A96: Domain | B96: Year | C96: EPC | D96: AP | E96: GF | F96: RE
A97: Climate change | B97: 2025 | C97: 0 | D97: 1 | E97: 0 | F97: 1
A98: Climate change | B98: 2050 | C98: 0 | D98: 1 | E98: 0 | F98: 1
A99: Climate change | B99: 2075 | C99: 0 | D99: 1 | E99: 0 | F99: 1
A100: Climate change | B100: 2100 | C100: 0 | D100: 1 | E100: 0 | F100: 1
A101: Freshwater use | B101: 2025 | C101: 0 | D101: 1 | E101: 0.9495 | F101: -
A102: Freshwater use | B102: 2050 | C102: 0 | D102: 1 | E102: 0.9475 | F102: -
A103: Freshwater use | B103: 2075 | C103: 0 | D103: 1 | E103: 0.9395 | F103: -
...

Sheet Table4_DNF_DWF
A1: Table 4 — Dynamic normalization and weighting factors (DNF, DWF): supporting calculations
A4: 1. Population (UN medium variant, UN DESA 2024; Supplementary Table S1)
A5: Population | C5: 2025 | D5: 2050 | E5: 2075 | F5: 2100
A6: Burkina Faso | B6: linked to PopulationTrajectory | C6: =PopulationTrajectory!B7 -> 24075000 | D6: =PopulationTrajectory!B8 -> 37304000 | E6: =PopulationTrajectory!B9 -> 46764000 | F6: =PopulationTrajectory!B10 -> 49846000
A7: World | B7: Supplementary Table S1 | C7: 8161973000 | D7: 9664379000 | E7: 10250493000 | F7: 10180161000
A9: 2. Inputs by indicator
A10: Scale | B10: Indicator (per-capita unit) | C10: Boundary | D10: Boundary unit | E10: Base-year footprint | F10: Footprint unit | G10: Factor to per-capita unit | H10: Base-year footprint per capita | J10: Source / note
A11: Global | B11: Climate (t CO₂eq) | C11: 5 | D11: Gt CO₂eq yr⁻¹ | E11: 16.85 | F11: Gt CO₂eq yr⁻¹ | G11: 1000000000 | H11: =E11*G11/C$7 -> 2.0644518 | J11: Table 1 central value; footprint = midpoint of 16–17.7
A12: Global | B12: Freshwater (10³ m³) | C12: 2500 | D12: km³ yr⁻¹ | E12: 1500 | F12: km³ yr⁻¹ | G12: 1000000 | H12: =E12*G12/C$7 -> 0.18377909 | J12: Table 1 central value; footprint = midpoint of 1,200–1,800
A13: Global | B13: Phosphorus (kg P) | C13: 8 | D13: Tg P yr⁻¹ | E13: 7.2 | F13: Tg P yr⁻¹ | G13: 1000000000 | H13: =E13*G13/C$7 -> 0.88213965 | J13: Table 1 values; see check in section 3
A14: Global | B14: Nitrogen (kg N) | C14: 90 | D14: Tg N yr⁻¹ | E14: 115 | F14: Tg N yr⁻¹ | G14: 1000000000 | H14: =E14*G14/C$7 -> 14.089731 | J14: Table 1 values; see check in section 3
A15: Global | B15: Cropland (ha) | C15: 1300 | D15: Mha | E15: 1573 | F15: Mha | G15: 1000000 | H15: =E15*G15/C$7 -> 0.19272301 | J15: Cropland sub-boundary 13 Mkm²; footprint ≈ FAOSTAT global cropland (implied by Table 4)
A16: Burkina Faso | B16: Climate (t CO₂eq) | C16: 14.75 | D16: Mt CO₂eq yr⁻¹ | E16: =2.71*C6/1000000 -> 65.24325 | F16: Mt CO₂eq yr⁻¹ | G16: 1000000 | H16: =E16*G16/C$6 -> 2.71 | J16: 2.71 t CO₂eq cap⁻¹ (Section 3.1.4) × 2025 population
A17: Burkina Faso | B17: Freshwater green water (10³ m³) | C17: 11.54 | D17: km³ yr⁻¹ | E17: 38.71 | F17: km³ yr⁻¹ | G17: 1000000 | H17: =E17*G17/C$6 -> 1.607892 | J17: Table 3; total available green water (Section 2.3)
A18: Burkina Faso | B18: Phosphorus fertilizer applied (kg P) | C18: =C13*1000000*E20/C15 -> 36923.077 | D18: t P yr⁻¹ | E18: 10339 | F18: t P yr⁻¹ | G18: 1000 | H18: =E18*G18/C$6 -> 0.42944964 | J18: Land-intensity downscaling: global boundary (C13, Tg P) x Burkina Faso cropland (E20, 6.0 Mha) / global cropland threshold (C15, 1,300 Mha) = 36,923 t P. Pressure: 2017 food-crop P (Sheet2 J14 23,688 t P2O5 x 0.4364 = 10,337; manuscript reports 10,339); cotton excluded
A19: Burkina Faso | B19: Nitrogen fertilizer applied (kg N) | C19: =C14*1000000*E20/C15 -> 415384.62 | D19: t N yr⁻¹ | E19: =Sheet2!G14 -> 41041 | F19: t N yr⁻¹ | G19: 1000 | H19: =E19*G19/C$6 -> 1.7047144 | J19: Land-intensity downscaling: global boundary (C14, Tg N) x cropland (E20) / C15 = 415,385 t N. Pressure: 2017 food-crop N (Sheet2 G14); cotton excluded
A20: Burkina Faso | B20: Cropland (ha) | C20: 4.97 | D20: Mha | E20: =LandSystemChange_Agri!B11 -> 6 | F20: Mha | G20: 1000000 | H20: =E20*G20/C$6 -> 0.24922118 | J20: Cropland sub-boundary; actual cropland 6.0 Mha
A24: Scale | B24: Indicator | C24: DNF 2025 | D24: DNF 2050 | E24: DNF 2075 | F24: DNF 2100 | G24: DWF 2025 | H24: DWF 2050 | I24: DWF 2075 | J24: DWF 2100 | N24: Pub. DNF 2075 | O24: Pub. DNF 2100 | P24: Pub. DWF 2025 | Q24: Pub. DWF 2050 | R24: Pub. DWF 2075 | S24: Pub. DWF 2100 | T24: Check (DNF ±0.2%, DWF ±0.01)
A25: =A11 -> Global | B25: =B11 -> Climate (t CO₂eq) | C25: =$C11*$G11/C$7 -> 0.61259698 | D25: =$C11*$G11/D$7 -> 0.51736382 | E25: =$C11*$G11/E$7 -> 0.48778142 | F25: =$C11*$G11/F$7 -> 0.49115137 | G25: =$H11/C25 -> 3.37 | H25: =$H11/D25 -> 3.990329 | I25: =$H11/E25 -> 4.2323298 | J25: =$H11/F25 -> 4.2032904 | L25: 0.613 | M25: 0.517 | N25: 0.488 | O25: 0.491 | P25: 3.37 | Q25: 3.99 | R25: 4.23 | S25: 4.2 | T25: =IF(((ABS(C25-L25)>0.0015)*(ABS(C25/L25-1)>0.002)+(ABS(D25-M25)>0.0015)*(ABS(D25/M25-1)>0.002)+(ABS(E25-N25)>0.0015)*(ABS(E25/N25-1)>0.002)+(ABS(F25-O25)>0.0015)*(ABS(F25/O25-1)>0.002)+(ABS(ROUND(G25,2)-P25)>0.0105)+(ABS(ROUND(H25,2)-Q25)>0.0105)+(ABS(ROUND(I25,2)-R25)>0.0105)+(ABS(ROUND(J25,2)-S25)>0.0105))=0,"OK","CHECK") -> OK
A26: =A12 -> Global | B26: =B12 -> Freshwater (10³ m³) | C26: =$C12*$G12/C$7 -> 0.30629849 | D26: =$C12*$G12/D$7 -> 0.25868191 | E26: =$C12*$G12/E$7 -> 0.24389071 | F26: =$C12*$G12/F$7 -> 0.24557568 | G26: =$H12/C26 -> 0.6 | H26: =$H12/D26 -> 0.71044433 | I26: =$H12/E26 -> 0.75353053 | J26: =$H12/F26 -> 0.7483603 | L26: 0.306 | M26: 0.259 | N26: 0.244 | O26: 0.246 | P26: 0.6 | Q26: 0.71 | R26: 0.75 | S26: 0.75 | T26: =IF(((ABS(C26-L26)>0.0015)*(ABS(C26/L26-1)>0.002)+(ABS(D26-M26)>0.0015)*(ABS(D26/M26-1)>0.002)+(ABS(E26-N26)>0.0015)*(ABS(E26/N26-1)>0.002)+(ABS(F26-O26)>0.0015)*(ABS(F26/O26-1)>0.002)+(ABS(ROUND(G26,2)-P26)>0.0105)+(ABS(ROUND(H26,2)-Q26)>0.0105)+(ABS(ROUND(I26,2)-R26)>0.0105)+(ABS(ROUND(J26,2)-S26)>0.0105))=0,"OK","CHECK") -> OK
A27: =A13 -> Global | B27: =B13 -> Phosphorus (kg P) | C27: =$C13*$G13/C$7 -> 0.98015517 | D27: =$C13*$G13/D$7 -> 0.82778211 | E27: =$C13*$G13/E$7 -> 0.78045027 | F27: =$C13*$G13/F$7 -> 0.78584219 | G27: =$H13/C27 -> 0.9 | H27: =$H13/D27 -> 1.0656665 | I27: =$H13/E27 -> 1.1302958 | J27: =$H13/F27 -> 1.1225405 | L27: 0.98 | M27: 0.828 | N27: 0.78 | O27: 0.786 | P27: 0.9 | Q27: 1.07 | R27: 1.13 | S27: 1.12 | T27: =IF(((ABS(C27-L27)>0.0015)*(ABS(C27/L27-1)>0.002)+(ABS(D27-M27)>0.0015)*(ABS(D27/M27-1)>0.002)+(ABS(E27-N27)>0.0015)*(ABS(E27/N27-1)>0.002)+(ABS(F27-O27)>0.0015)*(ABS(F27/O27-1)>0.002)+(ABS(ROUND(G27,2)-P27)>0.0105)+(ABS(ROUND(H27,2)-Q27)>0.0105)+(ABS(ROUND(I27,2)-R27)>0.0105)+(ABS(ROUND(J27,2)-S27)>0.0105))=0,"OK","CHECK") -> OK
A28: =A14 -> Global | B28: =B14 -> Nitrogen (kg N) | C28: =$C14*$G14/C$7 -> 11.026746 | D28: =$C14*$G14/D$7 -> 9.3125487 | E28: =$C14*$G14/E$7 -> 8.7800655 | F28: =$C14*$G14/F$7 -> 8.8407246 | G28: =$H14/C28 -> 1.2777778 | H28: =$H14/D28 -> 1.5129833 | I28: =$H14/E28 -> 1.6047409 | J28: =$H14/F28 -> 1.5937303 | L28: 11.027 | M28: 9.313 | N28: 8.78 | O28: 8.841 | P28: 1.28 | Q28: 1.51 | R28: 1.6 | S28: 1.59 | T28: =IF(((ABS(C28-L28)>0.0015)*(ABS(C28/L28-1)>0.002)+(ABS(D28-M28)>0.0015)*(ABS(D28/M28-1)>0.002)+(ABS(E28-N28)>0.0015)*(ABS(E28/N28-1)>0.002)+(ABS(F28-O28)>0.0015)*(ABS(F28/O28-1)>0.002)+(ABS(ROUND(G28,2)-P28)>0.0105)+(ABS(ROUND(H28,2)-Q28)>0.0105)+(ABS(ROUND(I28,2)-R28)>0.0105)+(ABS(ROUND(J28,2)-S28)>0.0105))=0,"OK","CHECK") -> OK
A29: =A15 -> Global | B29: =B15 -> Cropland (ha) | C29: =$C15*$G15/C$7 -> 0.15927521 | D29: =$C15*$G15/D$7 -> 0.13451459 | E29: =$C15*$G15/E$7 -> 0.12682317 | F29: =$C15*$G15/F$7 -> 0.12769936 | G29: =$H15/C29 -> 1.21 | H29: =$H15/D29 -> 1.4327294 | I29: =$H15/E29 -> 1.5196199 | J29: =$H15/F29 -> 1.5091933 | L29: 0.159 | M29: 0.135 | N29: 0.127 | O29: 0.128 | P29: 1.21 | Q29: 1.43 | R29: 1.52 | S29: 1.51 | T29: =IF(((ABS(C29-L29)>0.0015)*(ABS(C29/L29-1)>0.002)+(ABS(D29-M29)>0.0015)*(ABS(D29/M29-1)>0.002)+(ABS(E29-N29)>0.0015)*(ABS(E29/N29-1)>0.002)+(ABS(F29-O29)>0.0015)*(ABS(F29/O29-1)>0.002)+(ABS(ROUND(G29,2)-P29)>0.0105)+(ABS(ROUND(H29,2)-Q29)>0.0105)+(ABS(ROUND(I29,2)-R29)>0.0105)+(ABS(ROUND(J29,2)-S29)>0.0105))=0,"OK","CHECK") -> OK
A30: =A16 -> Burkina Faso | B30: =B16 -> Climate (t CO₂eq) | C30: =$C16*$G16/C$6 -> 0.61266874 | D30: =$C16*$G16/D$6 -> 0.39539996 | E30: =$C16*$G16/E$6 -> 0.31541357 | F30: =$C16*$G16/F$6 -> 0.29591141 | G30: =$H16/C30 -> 4.4232712 | H30: =$H16/D30 -> 6.8538197 | I30: =$H16/E30 -> 8.5918942 | J30: =$H16/F30 -> 9.1581464 | L30: 0.613 | M30: 0.395 | N30: 0.315 | O30: 0.296 | P30: 4.42 | Q30: 6.85 | R30: 8.59 | S30: 9.16 | T30: =IF(((ABS(C30-L30)>0.0015)*(ABS(C30/L30-1)>0.002)+(ABS(D30-M30)>0.0015)*(ABS(D30/M30-1)>0.002)+(ABS(E30-N30)>0.0015)*(ABS(E30/N30-1)>0.002)+(ABS(F30-O30)>0.0015)*(ABS(F30/O30-1)>0.002)+(ABS(ROUND(G30,2)-P30)>0.0105)+(ABS(ROUND(H30,2)-Q30)>0.0105)+(ABS(ROUND(I30,2)-R30)>0.0105)+(ABS(ROUND(J30,2)-S30)>0.0105))=0,"OK","CHECK") -> OK
A31: =A17 -> Burkina Faso | B31: =B17 -> Freshwater green water (10³ m³) | C31: =$C17*$G17/C$6 -> 0.47933541 | D31: =$C17*$G17/D$6 -> 0.3093502 | E31: =$C17*$G17/E$6 -> 0.24677102 | F31: =$C17*$G17/F$6 -> 0.23151306 | G31: =$H17/C31 -> 3.3544194 | H31: =$H17/D31 -> 5.1976433 | I31: =$H17/E31 -> 6.5157246 | J31: =$H17/F31 -> 6.945146 | L31: 0.479 | M31: 0.309 | N31: 0.247 | O31: 0.232 | P31: 3.36 | Q31: 5.2 | R31: 6.52 | S31: 6.95 | T31: =IF(((ABS(C31-L31)>0.0015)*(ABS(C31/L31-1)>0.002)+(ABS(D31-M31)>0.0015)*(ABS(D31/M31-1)>0.002)+(ABS(E31-N31)>0.0015)*(ABS(E31/N31-1)>0.002)+(ABS(F31-O31)>0.0015)*(ABS(F31/O31-1)>0.002)+(ABS(ROUND(G31,2)-P31)>0.0105)+(ABS(ROUND(H31,2)-Q31)>0.0105)+(ABS(ROUND(I31,2)-R31)>0.0105)+(ABS(ROUND(J31,2)-S31)>0.0105))=0,"OK","CHECK") -> OK
A32: =A18 -> Burkina Faso | B32: =B18 -> Phosphorus fertilizer applied (kg P) | C32: =$C18*$G18/C$6 -> 1.5336688 | D32: =$C18*$G18/D$6 -> 0.98978868 | E32: =$C18*$G18/E$6 -> 0.78956199 | F32: =$C18*$G18/F$6 -> 0.74074303 | G32: =$H18/C32 -> 0.28001458 | H32: =$H18/D32 -> 0.43388013 | I32: =$H18/E32 -> 0.5439087 | J32: =$H18/F32 -> 0.57975522 | L32: 1.534 | M32: 0.99 | N32: 0.79 | O32: 0.741 | P32: 0.28 | Q32: 0.43 | R32: 0.54 | S32: 0.58 | T32: =IF(((ABS(C32-L32)>0.0015)*(ABS(C32/L32-1)>0.002)+(ABS(D32-M32)>0.0015)*(ABS(D32/M32-1)>0.002)+(ABS(E32-N32)>0.0015)*(ABS(E32/N32-1)>0.002)+(ABS(F32-O32)>0.0015)*(ABS(F32/O32-1)>0.002)+(ABS(ROUND(G32,2)-P32)>0.0105)+(ABS(ROUND(H32,2)-Q32)>0.0105)+(ABS(ROUND(I32,2)-R32)>0.0105)+(ABS(ROUND(J32,2)-S32)>0.0105))=0,"OK","CHECK") -> OK
A33: =A19 -> Burkina Faso | B33: =B19 -> Nitrogen fertilizer applied (kg N) | C33: =$C19*$G19/C$6 -> 17.253774 | D33: =$C19*$G19/D$6 -> 11.135123 | E33: =$C19*$G19/E$6 -> 8.8825724 | F33: =$C19*$G19/F$6 -> 8.3333591 | G33: =$H19/C33 -> 0.098802407 | H33: =$H19/D33 -> 0.15309346 | I33: =$H19/E33 -> 0.19191675 | J33: =$H19/F33 -> 0.2045651 | L33: 17.254 | M33: 11.135 | N33: 8.883 | O33: 8.333 | P33: 0.1 | Q33: 0.15 | R33: 0.19 | S33: 0.2 | T33: =IF(((ABS(C33-L33)>0.0015)*(ABS(C33/L33-1)>0.002)+(ABS(D33-M33)>0.0015)*(ABS(D33/M33-1)>0.002)+(ABS(E33-N33)>0.0015)*(ABS(E33/N33-1)>0.002)+(ABS(F33-O33)>0.0015)*(ABS(F33/O33-1)>0.002)+(ABS(ROUND(G33,2)-P33)>0.0105)+(ABS(ROUND(H33,2)-Q33)>0.0105)+(ABS(ROUND(I33,2)-R33)>0.0105)+(ABS(ROUND(J33,2)-S33)>0.0105))=0,"OK","CHECK") -> OK
A34: =A20 -> Burkina Faso | B34: =B20 -> Cropland (ha) | C34: =$C20*$G20/C$6 -> 0.20643821 | D34: =$C20*$G20/D$6 -> 0.13322968 | E34: =$C20*$G20/E$6 -> 0.10627833 | F34: =$C20*$G20/F$6 -> 0.099707098 | G34: =$H20/C34 -> 1.2072435 | H34: =$H20/D34 -> 1.8706131 | I34: =$H20/E34 -> 2.3449858 | J34: =$H20/F34 -> 2.499533 | L34: 0.206 | M34: 0.133 | N34: 0.106 | O34: 0.1 | P34: 1.21 | Q34: 1.87 | R34: 2.35 | S34: 2.5 | T34: =IF(((ABS(C34-L34)>0.0015)*(ABS(C34/L34-1)>0.002)+(ABS(D34-M34)>0.0015)*(ABS(D34/M34-1)>0.002)+(ABS(E34-N34)>0.0015)*(ABS(E34/N34-1)>0.002)+(ABS(F34-O34)>0.0015)*(ABS(F34/O34-1)>0.002)+(ABS(ROUND(G34,2)-P34)>0.0105)+(ABS(ROUND(H34,2)-Q34)>0.0105)+(ABS(ROUND(I34,2)-R34)>0.0105)+(ABS(ROUND(J34,2)-S34)>0.0105))=0,"OK","CHECK") -> OK

Sheet FoodSecurity_Land
A1: Food-security land requirement (whole-cropland test) — Eqs. 5–8, Section 3.3; cereal-specific test in FoodSecurity_Cereal
A2: M = Pop × kcal × 365 × λ / κ × θ; L = M / Y. Blue = input; black = formula. Required yield on the cropland boundary here is the lower bound (all boundary cropland assigned to cereals).
A4: 1. Inputs
A5: Parameter | B5: Value | G5: Source
A6: Cereal share of dietary energy, λ | B6: 0.53 | G6: Section 2.1 [8]
A7: Blended cereal energy content, κ (kcal kg⁻¹) | B7: 3400 | G7: Section 2.1
A8: Loss and other-use factor, θ | B8: 1.214 | G8: Supplementary Table S4 (2013–2019 mean)
A9: Baseline cereal yield, Y (t ha⁻¹) | B9: =FoodSecurity_Cereal!B20 -> 1.19 | G9: FoodSecurity_Cereal!B20: World Bank mean 2019–2023 (FAO data), 1.188 rounded to 1.19.
A10: Actual cropland (Mha) | B10: =LandSystemChange_Agri!B11 -> 6 | G10: LandSystemChange_Agri!B11
A11: Cropland sub-boundary (Mha) | B11: 4.97 | G11: Section 3.1.3 / Table 4
A13: Population | B13: 2025 | C13: 2050 | D13: 2075 | E13: 2100
A14: Burkina Faso population | B14: =PopulationTrajectory!B7 -> 24075000 | C14: =PopulationTrajectory!B8 -> 37304000 | D14: =PopulationTrajectory!B9 -> 46764000 | E14: =PopulationTrajectory!B10 -> 49846000
A16: 2. Results by dietary scenario
A17: 2,700 kcal cap⁻¹ d⁻¹ | B17: 2025 | C17: 2050 | D17: 2075 | E17: 2100
A18: Required cereal production, M (Mt) | B18: =B$14*2700*365*$B$6/$B$7*$B$8/1000000000 -> 4.4899196 | C18: =C$14*2700*365*$B$6/$B$7*$B$8/1000000000 -> 6.9570908 | D18: =D$14*2700*365*$B$6/$B$7*$B$8/1000000000 -> 8.7213541 | E18: =E$14*2700*365*$B$6/$B$7*$B$8/1000000000 -> 9.2961384
A19: Required land at baseline yield, L (Mha) | B19: =B18/$B$9 -> 3.7730417 | C19: =C18/$B$9 -> 5.8462948 | D19: =D18/$B$9 -> 7.328869 | E19: =E18/$B$9 -> 7.811881
A20: Share of actual cropland | B20: =B19/$B$10 -> 0.62884028 | C20: =C19/$B$10 -> 0.97438246 | D20: =D19/$B$10 -> 1.2214782 | E20: =E19/$B$10 -> 1.3019802
A21: Share of cropland boundary (4.97 Mha) | B21: =B19/$B$11 -> 0.75916332 | C21: =C19/$B$11 -> 1.1763169 | D21: =D19/$B$11 -> 1.4746215 | E21: =E19/$B$11 -> 1.571807
A22: Required yield if all boundary cropland went to cereals (t ha⁻¹; lower bound) | B22: =B18/$B$11 -> 0.90340434 | C22: =C18/$B$11 -> 1.3998171 | D22: =D18/$B$11 -> 1.7547996 | E22: =E18/$B$11 -> 1.8704504
A24: 2,850 kcal cap⁻¹ d⁻¹ | B24: 2025 | C24: 2050 | D24: 2075 | E24: 2100
A25: Required cereal production, M (Mt) | B25: =B$14*2850*365*$B$6/$B$7*$B$8/1000000000 -> 4.7393596 | C25: =C$14*2850*365*$B$6/$B$7*$B$8/1000000000 -> 7.3435958 | D25: =D$14*2850*365*$B$6/$B$7*$B$8/1000000000 -> 9.2058738 | E25: =E$14*2850*365*$B$6/$B$7*$B$8/1000000000 -> 9.8125905
A26: Required land at baseline yield, L (Mha) | B26: =B25/$B$9 -> 3.9826551 | C26: =C25/$B$9 -> 6.1710889 | D26: =D25/$B$9 -> 7.7360284 | E26: =E25/$B$9 -> 8.2458744
A27: Share of actual cropland | B27: =B26/$B$10 -> 0.66377585 | C27: =C26/$B$10 -> 1.0285148 | D27: =D26/$B$10 -> 1.2893381 | E27: =E26/$B$10 -> 1.3743124
A28: Share of cropland boundary (4.97 Mha) | B28: =B26/$B$11 -> 0.80133905 | C28: =C26/$B$11 -> 1.2416678 | D28: =D26/$B$11 -> 1.5565449 | E28: =E26/$B$11 -> 1.6591297
A29: Required yield if all boundary cropland went to cereals (t ha⁻¹; lower bound) | B29: =B25/$B$11 -> 0.95359348 | C29: =C25/$B$11 -> 1.4775847 | D29: =D25/$B$11 -> 1.8522885 | E29: =E25/$B$11 -> 1.9743643
A31: 3,000 kcal cap⁻¹ d⁻¹ | B31: 2025 | C31: 2050 | D31: 2075 | E31: 2100
A32: Required cereal production, M (Mt) | B32: =B$14*3000*365*$B$6/$B$7*$B$8/1000000000 -> 4.9887995 | C32: =C$14*3000*365*$B$6/$B$7*$B$8/1000000000 -> 7.7301009 | D32: =D$14*3000*365*$B$6/$B$7*$B$8/1000000000 -> 9.6903934 | E32: =E$14*3000*365*$B$6/$B$7*$B$8/1000000000 -> 10.329043
A33: Required land at baseline yield, L (Mha) | B33: =B32/$B$9 -> 4.1922685 | C33: =C32/$B$9 -> 6.4958831 | D33: =D32/$B$9 -> 8.1431878 | E33: =E32/$B$9 -> 8.6798678
A34: Share of actual cropland | B34: =B33/$B$10 -> 0.69871142 | C34: =C33/$B$10 -> 1.0826472 | D34: =D33/$B$10 -> 1.357198 | E34: =E33/$B$10 -> 1.4466446
A35: Share of cropland boundary (4.97 Mha) | B35: =B33/$B$11 -> 0.84351479 | C35: =C33/$B$11 -> 1.3070187 | D35: =D33/$B$11 -> 1.6384684 | E35: =E33/$B$11 -> 1.7464523
A36: Required yield if all boundary cropland went to cereals (t ha⁻¹; lower bound) | B36: =B32/$B$11 -> 1.0037826 | C36: =C32/$B$11 -> 1.5553523 | D36: =D32/$B$11 -> 1.9497774 | E36: =E32/$B$11 -> 2.0782782
A38: 3. Ranges across diets (as reported in Section 3.3)
A39: Metric | B39: 2025 | C39: 2050 | D39: 2075 | E39: 2100
A40: Share of actual cropland (min–max) | B40: =TEXT(B20*100,"0")&"–"&TEXT(B34*100,"0")&"%" -> 63–70% | C40: =TEXT(C20*100,"0")&"–"&TEXT(C34*100,"0")&"%" -> 97–108% | D40: =TEXT(D20*100,"0")&"–"&TEXT(D34*100,"0")&"%" -> 122–136% | E40: =TEXT(E20*100,"0")&"–"&TEXT(E34*100,"0")&"%" -> 130–145%
A41: Share of sub-boundary (min–max) | B41: =TEXT(B21*100,"0")&"–"&TEXT(B35*100,"0")&"%" -> 76–84% | C41: =TEXT(C21*100,"0")&"–"&TEXT(C35*100,"0")&"%" -> 118–131% | D41: =TEXT(D21*100,"0")&"–"&TEXT(D35*100,"0")&"%" -> 147–164% | E41: =TEXT(E21*100,"0")&"–"&TEXT(E35*100,"0")&"%" -> 157–175%
A42: Required yield, t ha⁻¹ (min–max) | B42: =TEXT(B22,"0.00")&"–"&TEXT(B36,"0.00") -> 0.90–1.00 | C42: =TEXT(C22,"0.00")&"–"&TEXT(C36,"0.00") -> 1.40–1.56 | D42: =TEXT(D22,"0.00")&"–"&TEXT(D36,"0.00") -> 1.75–1.95 | E42: =TEXT(E22,"0.00")&"–"&TEXT(E36,"0.00") -> 1.87–2.08
A43: Annual yield growth to 2100, central diet (lower bound; see FoodSecurity_Cereal for the cereal-specific rate) | B43: =(E29/$B$9)^(1/75)-1 -> 0.006773412
A44: Cereal-specific test (Eq. 8; Tables 5, S5, S8): see sheet FoodSecurity_Cereal.
A45: 4. Sensitivity to cropland area (2,850 kcal, whole-cropland test)
A46: Cropland assumption (Mha) | B46: Land / actual, 2025 | C46: Land / actual, 2100 | D46: Downscaled boundary (Mha)
...

Sheet FoodSecurity_Cereal
A1: Cereal-specific food-security test — Eq. 8, Section 3.3, Table 5, Figure 7, Supplementary Tables S5 and S8
A2: Boundary-compliant cereal land = (cereal area / cropland) × cropland boundary; required yield Y* = M / boundary cereal land. Blue = input; black = formula. Cereal series: World Bank WDI indicators AG.LND.CREL.HA, AG.YLD.CREL.KG, AG.PRD.CREL.MT (FAO data; World Bank, 2026b).
A4: 1. World Bank cereal series, Burkina Faso
A5: Year | B5: Cereal area (ha) | C5: Yield (kg ha⁻¹) | D5: Production (t) | E5: Area × yield (t) | F5: Area × yield / production − 1
A6: 2015 | B6: 3584230 | C6: 1168.9 | D6: 4189665 | E6: =B6*C6/1000 -> 4189606.4 | F6: =E6/D6-1 -> -1.397558e-05
A7: 2016 | B7: 4017586 | C7: 1136.8 | D7: 4567066 | E7: =B7*C7/1000 -> 4567191.8 | F7: =E7/D7-1 -> 2.7537329e-05
A8: 2017 | B8: 4026919 | C8: 1009 | D8: 4063197 | E8: =B8*C8/1000 -> 4063161.3 | F8: =E8/D8-1 -> -8.7933221e-06
A9: 2018 | B9: 4495792 | C9: 1152.3 | D9: 5180702 | E9: =B9*C9/1000 -> 5180501.1 | F9: =E9/D9-1 -> -3.8774359e-05
A10: 2019 | B10: 4272786 | C10: 1156.1 | D10: 4939630 | E10: =B10*C10/1000 -> 4939767.9 | F10: =E10/D10-1 -> 2.7915978e-05
A11: 2020 | B11: 4104826 | C11: 1261.7 | D11: 5179104 | E11: =B11*C11/1000 -> 5179059 | F11: =E11/D11-1 -> -8.695674e-06
A12: 2021 | B12: 4254016 | C12: 1095.7 | D12: 4661140 | E12: =B12*C12/1000 -> 4661125.3 | F12: =E12/D12-1 -> -3.1470413e-06
A13: 2022 | B13: 4301063 | C13: 1204.1 | D13: 5179059 | E13: =B13*C13/1000 -> 5178910 | F13: =E13/D13-1 -> -2.8777757e-05
A14: 2023 | B14: 4215867 | C14: 1221.1 | D14: 5147924 | E14: =B14*C14/1000 -> 5147995.2 | F14: =E14/D14-1 -> 1.3829594e-05
A15: Mean 2019–2023 | B15: =AVERAGE(B10:B14) -> 4229711.6 | C15: =AVERAGE(C10:C14) -> 1187.74 | D15: =AVERAGE(D10:D14) -> 5021371.4 | E15: =AVERAGE(E10:E14) -> 5021371.5 | G15: National ministry: 4.2 Mha mean cereal area, 2019/20–2023/24 (Ecofin, 2026); agrees.
A17: 2. Inputs
A18: Parameter | B18: Value | G18: Source
A19: Present cereal area, A_cer (Mha) | B19: =ROUND(B15/1000000,2) -> 4.23 | G19: Mean 2019–2023 of the World Bank series (row 15)
A20: Baseline cereal yield, Y (t ha⁻¹) | B20: =ROUND(C15/1000,2) -> 1.19 | G20: Mean 2019–2023 (1.188 rounded); production 5.02 Mt / area 4.23 Mha = 1.19
A21: Actual cropland (Mha) | B21: =FoodSecurity_Land!B10 -> 6 | G21: LandSystemChange_Agri!B11
A22: Cropland boundary, SOS_crop (Mha) | B22: =FoodSecurity_Land!B11 -> 4.97 | G22: Table 4 / Table 2
A23: Cropland ratio (actual / boundary) | B23: =B21/B22 -> 1.2072435 | G23: Computed
A24: Boundary-compliant cereal land, L_SOS,cer (Mha) | B24: =B19*B22/B21 -> 3.50385 | G24: Eq. 8: (A_cer / cropland) × SOS_crop = A_cer / cropland ratio
A25: Superseded baseline yield (t ha⁻¹) | B25: 1.44 | G25: Midpoint of 0.92–1.95 range of crop-specific yields; used only in the sensitivity table
A27: 3. Results by dietary scenario (loss and other-use factor θ, λ, κ from FoodSecurity_Land)
A28: 2,700 kcal cap⁻¹ d⁻¹ | B28: 2025 | C28: 2050 | D28: 2075 | E28: 2100
A29: Required cereal production, M (Mt) | B29: =FoodSecurity_Land!B18 -> 4.4899196 | C29: =FoodSecurity_Land!C18 -> 6.9570908 | D29: =FoodSecurity_Land!D18 -> 8.7213541 | E29: =FoodSecurity_Land!E18 -> 9.2961384
A30: Required land at baseline yield, L (Mha) | B30: =B29/$B$20 -> 3.7730417 | C30: =C29/$B$20 -> 5.8462948 | D30: =D29/$B$20 -> 7.328869 | E30: =E29/$B$20 -> 7.811881
A31: Share of present cereal area | B31: =B30/$B$19 -> 0.89197203 | C31: =C30/$B$19 -> 1.3821028 | D31: =D30/$B$19 -> 1.7325931 | E31: =E30/$B$19 -> 1.8467804
A32: Share of boundary-compliant cereal land | B32: =B30/$B$24 -> 1.0768274 | C32: =C30/$B$24 -> 1.6685345 | D32: =D30/$B$24 -> 2.0916617 | E32: =E30/$B$24 -> 2.2295135
A33: Required yield on boundary-compliant cereal land (t ha⁻¹) | B33: =B29/$B$24 -> 1.2814246 | C33: =C29/$B$24 -> 1.9855561 | D33: =D29/$B$24 -> 2.4890775 | E33: =E29/$B$24 -> 2.6531211
A34: Required yield if all boundary cropland went to cereals (t ha⁻¹; lower bound) | B34: =B29/$B$22 -> 0.90340434 | C34: =C29/$B$22 -> 1.3998171 | D34: =D29/$B$22 -> 1.7547996 | E34: =E29/$B$22 -> 1.8704504
A36: 2,850 kcal cap⁻¹ d⁻¹ | B36: 2025 | C36: 2050 | D36: 2075 | E36: 2100
A37: Required cereal production, M (Mt) | B37: =FoodSecurity_Land!B25 -> 4.7393596 | C37: =FoodSecurity_Land!C25 -> 7.3435958 | D37: =FoodSecurity_Land!D25 -> 9.2058738 | E37: =FoodSecurity_Land!E25 -> 9.8125905
A38: Required land at baseline yield, L (Mha) | B38: =B37/$B$20 -> 3.9826551 | C38: =C37/$B$20 -> 6.1710889 | D38: =D37/$B$20 -> 7.7360284 | E38: =E37/$B$20 -> 8.2458744
A39: Share of present cereal area | B39: =B38/$B$19 -> 0.94152603 | C39: =C38/$B$19 -> 1.4588863 | D39: =D38/$B$19 -> 1.8288483 | E39: =E38/$B$19 -> 1.9493793
A40: Share of boundary-compliant cereal land | B40: =B38/$B$24 -> 1.1366511 | C40: =C38/$B$24 -> 1.7612309 | D40: =D38/$B$24 -> 2.2078652 | E40: =E38/$B$24 -> 2.3533754
A41: Required yield on boundary-compliant cereal land (t ha⁻¹) | B41: =B37/$B$24 -> 1.3526149 | C41: =C37/$B$24 -> 2.0958648 | D41: =D37/$B$24 -> 2.6273596 | E41: =E37/$B$24 -> 2.8005167
A42: Required yield if all boundary cropland went to cereals (t ha⁻¹; lower bound) | B42: =B37/$B$22 -> 0.95359348 | C42: =C37/$B$22 -> 1.4775847 | D42: =D37/$B$22 -> 1.8522885 | E42: =E37/$B$22 -> 1.9743643
A44: 3,000 kcal cap⁻¹ d⁻¹ | B44: 2025 | C44: 2050 | D44: 2075 | E44: 2100
A45: Required cereal production, M (Mt) | B45: =FoodSecurity_Land!B32 -> 4.9887995 | C45: =FoodSecurity_Land!C32 -> 7.7301009 | D45: =FoodSecurity_Land!D32 -> 9.6903934 | E45: =FoodSecurity_Land!E32 -> 10.329043
...

Sheet MonteCarlo_Robustness
A1: Boundary-value Monte Carlo (Supplementary Tables S6, S7, S8) and Figure 2 classification
A2: Monte Carlo outputs
A4: 1. Table S6 — downscaled per-capita boundary (N = 1,000) | H4: 4. Figure 2 — performance (P), trend (T) and confidence (C)
A5: Domain | B5: Year | C5: Median | D5: 5th pct | E5: 95th pct | F5: Unit | H5: Domain | I5: Year | J5: DWF (Table 4) | K5: P: performance | L5: T: trend 2025→2100 | M5: C: confidence
A6: Climate | B6: 2025 | C6: 0.62 | D6: 0.59 | E6: 0.65 | F6: t CO₂eq cap⁻¹ | H6: Climate | I6: 2025 | J6: =Table4_DNF_DWF!G30 -> 4.4232712 | K6: =IF(J6<1,"Below boundary (safe)",IF(J6<=2,"Zone of uncertainty","High risk")) -> High risk | L6: =IF(Table4_DNF_DWF!J30-Table4_DNF_DWF!G30>1,"Rapidly deteriorating","Deteriorating") -> Rapidly deteriorating | M6: =IF(IF(J6>1,F29,1-F29)>=0.95,"High",IF(IF(J6>1,F29,1-F29)>=0.8,"Medium","Low")) -> High
A7: Climate | B7: 2050 | C7: 0.4 | D7: 0.38 | E7: 0.42 | F7: t CO₂eq cap⁻¹ | H7: Climate | I7: 2050 | J7: =Table4_DNF_DWF!H30 -> 6.8538197 | K7: =IF(J7<1,"Below boundary (safe)",IF(J7<=2,"Zone of uncertainty","High risk")) -> High risk | L7: =IF(Table4_DNF_DWF!J30-Table4_DNF_DWF!G30>1,"Rapidly deteriorating","Deteriorating") -> Rapidly deteriorating | M7: =IF(IF(J7>1,F30,1-F30)>=0.95,"High",IF(IF(J7>1,F30,1-F30)>=0.8,"Medium","Low")) -> High
A8: Climate | B8: 2075 | C8: 0.32 | D8: 0.3 | E8: 0.33 | F8: t CO₂eq cap⁻¹ | H8: Climate | I8: 2075 | J8: =Table4_DNF_DWF!I30 -> 8.5918942 | K8: =IF(J8<1,"Below boundary (safe)",IF(J8<=2,"Zone of uncertainty","High risk")) -> High risk | L8: =IF(Table4_DNF_DWF!J30-Table4_DNF_DWF!G30>1,"Rapidly deteriorating","Deteriorating") -> Rapidly deteriorating | M8: =IF(IF(J8>1,F31,1-F31)>=0.95,"High",IF(IF(J8>1,F31,1-F31)>=0.8,"Medium","Low")) -> High
A9: Climate | B9: 2100 | C9: 0.3 | D9: 0.28 | E9: 0.31 | F9: t CO₂eq cap⁻¹ | H9: Climate | I9: 2100 | J9: =Table4_DNF_DWF!J30 -> 9.1581464 | K9: =IF(J9<1,"Below boundary (safe)",IF(J9<=2,"Zone of uncertainty","High risk")) -> High risk | L9: =IF(Table4_DNF_DWF!J30-Table4_DNF_DWF!G30>1,"Rapidly deteriorating","Deteriorating") -> Rapidly deteriorating | M9: =IF(IF(J9>1,F32,1-F32)>=0.95,"High",IF(IF(J9>1,F32,1-F32)>=0.8,"Medium","Low")) -> High
A10: Cropland | B10: 2025 | C10: 2063 | D10: 1855 | E10: 2279 | F10: m² cap⁻¹ | H10: Freshwater | I10: 2025 | J10: =Table4_DNF_DWF!G31 -> 3.3544194 | K10: =IF(J10<1,"Below boundary (safe)",IF(J10<=2,"Zone of uncertainty","High risk")) -> High risk | L10: =IF(Table4_DNF_DWF!J31-Table4_DNF_DWF!G31>1,"Rapidly deteriorating","Deteriorating") -> Rapidly deteriorating | M10: =IF(IF(J10>1,F33,1-F33)>=0.95,"High",IF(IF(J10>1,F33,1-F33)>=0.8,"Medium","Low")) -> High
A11: Cropland | B11: 2050 | C11: 1332 | D11: 1197 | E11: 1471 | F11: m² cap⁻¹ | H11: Freshwater | I11: 2050 | J11: =Table4_DNF_DWF!H31 -> 5.1976433 | K11: =IF(J11<1,"Below boundary (safe)",IF(J11<=2,"Zone of uncertainty","High risk")) -> High risk | L11: =IF(Table4_DNF_DWF!J31-Table4_DNF_DWF!G31>1,"Rapidly deteriorating","Deteriorating") -> Rapidly deteriorating | M11: =IF(IF(J11>1,F34,1-F34)>=0.95,"High",IF(IF(J11>1,F34,1-F34)>=0.8,"Medium","Low")) -> High
A12: Cropland | B12: 2075 | C12: 1062 | D12: 955 | E12: 1173 | F12: m² cap⁻¹ | H12: Freshwater | I12: 2075 | J12: =Table4_DNF_DWF!I31 -> 6.5157246 | K12: =IF(J12<1,"Below boundary (safe)",IF(J12<=2,"Zone of uncertainty","High risk")) -> High risk | L12: =IF(Table4_DNF_DWF!J31-Table4_DNF_DWF!G31>1,"Rapidly deteriorating","Deteriorating") -> Rapidly deteriorating | M12: =IF(IF(J12>1,F35,1-F35)>=0.95,"High",IF(IF(J12>1,F35,1-F35)>=0.8,"Medium","Low")) -> High
A13: Cropland | B13: 2100 | C13: 997 | D13: 896 | E13: 1101 | F13: m² cap⁻¹ | H13: Freshwater | I13: 2100 | J13: =Table4_DNF_DWF!J31 -> 6.945146 | K13: =IF(J13<1,"Below boundary (safe)",IF(J13<=2,"Zone of uncertainty","High risk")) -> High risk | L13: =IF(Table4_DNF_DWF!J31-Table4_DNF_DWF!G31>1,"Rapidly deteriorating","Deteriorating") -> Rapidly deteriorating | M13: =IF(IF(J13>1,F36,1-F36)>=0.95,"High",IF(IF(J13>1,F36,1-F36)>=0.8,"Medium","Low")) -> High
A14: Freshwater | B14: 2025 | C14: 474 | D14: 280 | E14: 667 | F14: m³ cap⁻¹ | H14: Cropland | I14: 2025 | J14: =Table4_DNF_DWF!G34 -> 1.2072435 | K14: =IF(J14<1,"Below boundary (safe)",IF(J14<=2,"Zone of uncertainty","High risk")) -> Zone of uncertainty | L14: =IF(Table4_DNF_DWF!J34-Table4_DNF_DWF!G34>1,"Rapidly deteriorating","Deteriorating") -> Rapidly deteriorating | M14: =IF(IF(J14>1,F37,1-F37)>=0.95,"High",IF(IF(J14>1,F37,1-F37)>=0.8,"Medium","Low")) -> High
A15: Freshwater | B15: 2050 | C15: 306 | D15: 181 | E15: 431 | F15: m³ cap⁻¹ | H15: Cropland | I15: 2050 | J15: =Table4_DNF_DWF!H34 -> 1.8706131 | K15: =IF(J15<1,"Below boundary (safe)",IF(J15<=2,"Zone of uncertainty","High risk")) -> Zone of uncertainty | L15: =IF(Table4_DNF_DWF!J34-Table4_DNF_DWF!G34>1,"Rapidly deteriorating","Deteriorating") -> Rapidly deteriorating | M15: =IF(IF(J15>1,F38,1-F38)>=0.95,"High",IF(IF(J15>1,F38,1-F38)>=0.8,"Medium","Low")) -> High
A16: Freshwater | B16: 2075 | C16: 244 | D16: 144 | E16: 343 | F16: m³ cap⁻¹ | H16: Cropland | I16: 2075 | J16: =Table4_DNF_DWF!I34 -> 2.3449858 | K16: =IF(J16<1,"Below boundary (safe)",IF(J16<=2,"Zone of uncertainty","High risk")) -> High risk | L16: =IF(Table4_DNF_DWF!J34-Table4_DNF_DWF!G34>1,"Rapidly deteriorating","Deteriorating") -> Rapidly deteriorating | M16: =IF(IF(J16>1,F39,1-F39)>=0.95,"High",IF(IF(J16>1,F39,1-F39)>=0.8,"Medium","Low")) -> High
A17: Freshwater | B17: 2100 | C17: 229 | D17: 135 | E17: 322 | F17: m³ cap⁻¹ | H17: Cropland | I17: 2100 | J17: =Table4_DNF_DWF!J34 -> 2.499533 | K17: =IF(J17<1,"Below boundary (safe)",IF(J17<=2,"Zone of uncertainty","High risk")) -> High risk | L17: =IF(Table4_DNF_DWF!J34-Table4_DNF_DWF!G34>1,"Rapidly deteriorating","Deteriorating") -> Rapidly deteriorating | M17: =IF(IF(J17>1,F40,1-F40)>=0.95,"High",IF(IF(J17>1,F40,1-F40)>=0.8,"Medium","Low")) -> High
A18: Nitrogen | B18: 2025 | C18: 18.35 | D18: 14.23 | E18: 23.99 | F18: kg N cap⁻¹ | H18: Phosphorus | I18: 2025 | J18: =Table4_DNF_DWF!G32 -> 0.28001458 | K18: =IF(J18<1,"Below boundary (safe)",IF(J18<=2,"Zone of uncertainty","High risk")) -> Below boundary (safe) | L18: =IF(Table4_DNF_DWF!J32-Table4_DNF_DWF!G32>1,"Rapidly deteriorating","Deteriorating") -> Deteriorating | M18: =IF(IF(J18>1,F41,1-F41)>=0.95,"High",IF(IF(J18>1,F41,1-F41)>=0.8,"Medium","Low")) -> High
A19: Nitrogen | B19: 2050 | C19: 11.84 | D19: 9.19 | E19: 15.48 | F19: kg N cap⁻¹ | H19: Phosphorus | I19: 2050 | J19: =Table4_DNF_DWF!H32 -> 0.43388013 | K19: =IF(J19<1,"Below boundary (safe)",IF(J19<=2,"Zone of uncertainty","High risk")) -> Below boundary (safe) | L19: =IF(Table4_DNF_DWF!J32-Table4_DNF_DWF!G32>1,"Rapidly deteriorating","Deteriorating") -> Deteriorating | M19: =IF(IF(J19>1,F42,1-F42)>=0.95,"High",IF(IF(J19>1,F42,1-F42)>=0.8,"Medium","Low")) -> High
A20: Nitrogen | B20: 2075 | C20: 9.45 | D20: 7.33 | E20: 12.35 | F20: kg N cap⁻¹ | H20: Phosphorus | I20: 2075 | J20: =Table4_DNF_DWF!I32 -> 0.5439087 | K20: =IF(J20<1,"Below boundary (safe)",IF(J20<=2,"Zone of uncertainty","High risk")) -> Below boundary (safe) | L20: =IF(Table4_DNF_DWF!J32-Table4_DNF_DWF!G32>1,"Rapidly deteriorating","Deteriorating") -> Deteriorating | M20: =IF(IF(J20>1,F43,1-F43)>=0.95,"High",IF(IF(J20>1,F43,1-F43)>=0.8,"Medium","Low")) -> High
A21: Nitrogen | B21: 2100 | C21: 8.86 | D21: 6.87 | E21: 11.59 | F21: kg N cap⁻¹ | H21: Phosphorus | I21: 2100 | J21: =Table4_DNF_DWF!J32 -> 0.57975522 | K21: =IF(J21<1,"Below boundary (safe)",IF(J21<=2,"Zone of uncertainty","High risk")) -> Below boundary (safe) | L21: =IF(Table4_DNF_DWF!J32-Table4_DNF_DWF!G32>1,"Rapidly deteriorating","Deteriorating") -> Deteriorating | M21: =IF(IF(J21>1,F44,1-F44)>=0.95,"High",IF(IF(J21>1,F44,1-F44)>=0.8,"Medium","Low")) -> High
A22: Phosphorus | B22: 2025 | C22: 1.86 | D22: 1.35 | E22: 2.72 | F22: kg P cap⁻¹ | H22: Nitrogen | I22: 2025 | J22: =Table4_DNF_DWF!G33 -> 0.098802407 | K22: =IF(J22<1,"Below boundary (safe)",IF(J22<=2,"Zone of uncertainty","High risk")) -> Below boundary (safe) | L22: =IF(Table4_DNF_DWF!J33-Table4_DNF_DWF!G33>1,"Rapidly deteriorating","Deteriorating") -> Deteriorating | M22: =IF(IF(J22>1,F45,1-F45)>=0.95,"High",IF(IF(J22>1,F45,1-F45)>=0.8,"Medium","Low")) -> High
A23: Phosphorus | B23: 2050 | C23: 1.2 | D23: 0.87 | E23: 1.75 | F23: kg P cap⁻¹ | H23: Nitrogen | I23: 2050 | J23: =Table4_DNF_DWF!H33 -> 0.15309346 | K23: =IF(J23<1,"Below boundary (safe)",IF(J23<=2,"Zone of uncertainty","High risk")) -> Below boundary (safe) | L23: =IF(Table4_DNF_DWF!J33-Table4_DNF_DWF!G33>1,"Rapidly deteriorating","Deteriorating") -> Deteriorating | M23: =IF(IF(J23>1,F46,1-F46)>=0.95,"High",IF(IF(J23>1,F46,1-F46)>=0.8,"Medium","Low")) -> High
A24: Phosphorus | B24: 2075 | C24: 0.96 | D24: 0.69 | E24: 1.4 | F24: kg P cap⁻¹ | H24: Nitrogen | I24: 2075 | J24: =Table4_DNF_DWF!I33 -> 0.19191675 | K24: =IF(J24<1,"Below boundary (safe)",IF(J24<=2,"Zone of uncertainty","High risk")) -> Below boundary (safe) | L24: =IF(Table4_DNF_DWF!J33-Table4_DNF_DWF!G33>1,"Rapidly deteriorating","Deteriorating") -> Deteriorating | M24: =IF(IF(J24>1,F47,1-F47)>=0.95,"High",IF(IF(J24>1,F47,1-F47)>=0.8,"Medium","Low")) -> High
A25: Phosphorus | B25: 2100 | C25: 0.9 | D25: 0.65 | E25: 1.31 | F25: kg P cap⁻¹ | H25: Nitrogen | I25: 2100 | J25: =Table4_DNF_DWF!J33 -> 0.2045651 | K25: =IF(J25<1,"Below boundary (safe)",IF(J25<=2,"Zone of uncertainty","High risk")) -> Below boundary (safe) | L25: =IF(Table4_DNF_DWF!J33-Table4_DNF_DWF!G33>1,"Rapidly deteriorating","Deteriorating") -> Deteriorating | M25: =IF(IF(J25>1,F48,1-F48)>=0.95,"High",IF(IF(J25>1,F48,1-F48)>=0.8,"Medium","Low")) -> High
A27: 2. Table S7 — pressure-to-boundary ratio (N = 2,000) | H27: P: < 1 safe; 1–2 zone of uncertainty; > 2 high risk. T: rapid if DWF rises by > 1 between 2025 and 2100. C: share of Monte Carlo draws agreeing with the deterministic status (≥ 95% high, 80–95% medium, < 80% low).
A28: Domain | B28: Year | C28: Median | D28: 5th pct | E28: 95th pct | F28: P(ratio > 1)
A29: Climate | B29: 2025 | C29: 4.4 | D29: 4.19 | E29: 4.61 | F29: 1
A30: Climate | B30: 2050 | C30: 6.82 | D30: 6.5 | E30: 7.13 | F30: 1
A31: Climate | B31: 2075 | C31: 8.56 | D31: 8.16 | E31: 8.96 | F31: 1
A32: Climate | B32: 2100 | C32: 9.13 | D32: 8.68 | E32: 9.53 | F32: 1
A33: Freshwater | B33: 2025 | C33: 3.38 | D33: 2.38 | E33: 5.76 | F33: 1
A34: Freshwater | B34: 2050 | C34: 5.23 | D34: 3.68 | E34: 8.92 | F34: 1
